[ 2024-11-08 21:27:15,033 ] 97 werkzeug - INFO - [31m[1mWARNING: This is a development server. Do not use it in a production deployment. Use a production WSGI server instead.[0m
 * Running on all addresses (0.0.0.0)
 * Running on http://127.0.0.1:5000
 * Running on http://10.110.7.36:5000
[ 2024-11-08 21:27:15,033 ] 97 werkzeug - INFO - [33mPress CTRL+C to quit[0m
[ 2024-11-08 21:27:31,217 ] 97 werkzeug - INFO - 127.0.0.1 - - [08/Nov/2024 21:27:31] "GET / HTTP/1.1" 200 -
[ 2024-11-08 21:27:35,514 ] 97 werkzeug - INFO - 127.0.0.1 - - [08/Nov/2024 21:27:35] "[33mGET /apple-touch-icon-precomposed.png HTTP/1.1[0m" 404 -
[ 2024-11-08 21:27:35,516 ] 97 werkzeug - INFO - 127.0.0.1 - - [08/Nov/2024 21:27:35] "[33mGET /apple-touch-icon.png HTTP/1.1[0m" 404 -
[ 2024-11-08 21:27:35,516 ] 97 werkzeug - INFO - 127.0.0.1 - - [08/Nov/2024 21:27:35] "[33mGET /favicon.ico HTTP/1.1[0m" 404 -
[ 2024-11-08 21:27:42,899 ] 97 werkzeug - INFO - 127.0.0.1 - - [08/Nov/2024 21:27:42] "GET / HTTP/1.1" 200 -
[ 2024-11-08 21:27:43,190 ] 97 werkzeug - INFO - 127.0.0.1 - - [08/Nov/2024 21:27:43] "[33mGET /favicon.ico HTTP/1.1[0m" 404 -
[ 2024-11-08 21:27:50,387 ] 97 werkzeug - INFO - 127.0.0.1 - - [08/Nov/2024 21:27:50] "GET /predictdata HTTP/1.1" 200 -
[ 2024-11-08 21:28:10,127 ] 838 app - ERROR - Exception on /predictdata [POST]
Traceback (most recent call last):
  File "/Users/kuchibhotlaanirudharaghavasarma/MLProjects/src/pipeline/predict_pipeline.py", line 13, in predict
    model_path=os.path.join("artifacts","model.pkl")
NameError: name 'os' is not defined

During handling of the above exception, another exception occurred:

Traceback (most recent call last):
  File "/Users/kuchibhotlaanirudharaghavasarma/MLProjects/venv/lib/python3.8/site-packages/flask/app.py", line 1473, in wsgi_app
    response = self.full_dispatch_request()
  File "/Users/kuchibhotlaanirudharaghavasarma/MLProjects/venv/lib/python3.8/site-packages/flask/app.py", line 882, in full_dispatch_request
    rv = self.handle_user_exception(e)
  File "/Users/kuchibhotlaanirudharaghavasarma/MLProjects/venv/lib/python3.8/site-packages/flask/app.py", line 880, in full_dispatch_request
    rv = self.dispatch_request()
  File "/Users/kuchibhotlaanirudharaghavasarma/MLProjects/venv/lib/python3.8/site-packages/flask/app.py", line 865, in dispatch_request
    return self.ensure_sync(self.view_functions[rule.endpoint])(**view_args)  # type: ignore[no-any-return]
  File "app.py", line 39, in predict_datapoint
    results=predict_pipeline.predict(pred_df)
  File "/Users/kuchibhotlaanirudharaghavasarma/MLProjects/src/pipeline/predict_pipeline.py", line 24, in predict
    raise CustomException(e,sys)
src.exception.CustomException: Error occured in python script name [/Users/kuchibhotlaanirudharaghavasarma/MLProjects/src/pipeline/predict_pipeline.py] line number [13] error message[name 'os' is not defined]
[ 2024-11-08 21:28:10,131 ] 97 werkzeug - INFO - 127.0.0.1 - - [08/Nov/2024 21:28:10] "[35m[1mPOST /predictdata HTTP/1.1[0m" 500 -
